Workbook
Name s3target: [1]ActivityList!$AW$8
Name s4target: [1]ActivityList!$AW$7
Name s5target: [1]ActivityList!$AW$6

Sheet ReadMe
A1: UKRAINE 2026 Humanitarain Needs & Response Plan
A2: People Affected, PIN & Severity Estimates | Activities, Response Targets & People Prioritized
A4: This data is shared for humanitarian purposes and should only be unsed in accordance with the Ukraine Infromation Sharing Proctol, May 2023.
A6: Notes:
A7: 1) The dataset is produced by the United Nations for the Coordination of Humanitarian Affairs (OCHA) in collaboration with humanitarian partners. It presents the number of people in need (PiN), the severity of those needs, the activities of the planned response, and the number of people to be reached with humanitarian assistance in Ukraine in 2026.
A8: 2) The data provided herein should be interpreted and used according to the Ukraine 2026 Humanitarian Needs and Response Plan (HNRP), which explains the strategic priorities and the basis for the selected response activities, planned reach and people to be prioritized. | B8: Link
A9: 3) The data sources and methodology for the derivation of the PIN and severity of needs is explained in Annex 4.3 of the Ukraine 2026 HNRP, "Analysis Methodology & Data Sources", which desribes the baseline and affected population estimates, and the analytical methodology tailored to the strategic priority framework. | B9: Link
A10: 4) Abreviations List: SP = Strategic Priority ED = Education (Cluster) FL = Food Security & Livelihoods (Cluster) FS = Food Security (part of Cluster) LI = Livelihoods (part of Cluster) HE = Health (Cluster) PR = Protection (Cluster) GP = Protection (part of Cluster) CP = Child Protection (part of Cluster) GB = Gender-Based Violence (part of Cluster) SN = Shelter & NFIs (Cluster) WA = WASH (Cluster) CW = Cash Working Group UC = Unified Cash Transfer AoR = Area of Responsbility IDP = Internally-Displaced People WAND = War-Affected Non-Displaced People PiN = People in Need
A11: 5) Contact: UN-OCHA Ukraine IMU, ocha-ukr-im@un.org

Sheet ActivityList
A1: UKRAINE 2026 HNRP
A2: List of Activities and Requirements for Government Controlled Areas
A3: Release Date: 13 January 2026
A5: # | B5: Cluster | C5: Cluster Code | D5: Activity Name | E5: Strategic Objective | F5: Activity Code | G5: Modality | H5: Type of Needs | I5: Recipient | J5: Strategic Priority | K5: Activity Unit | L5: Target (individuals to be reached) | O5: Activity | P5: Prioritized Target | S5: Prioritized Activity
L6: IDPs | M6: WAND | N6: Overall | O6: Cost (USD) | P6: IDPs | Q6: WAND | R6: Overall | S6: Cost (USD)
A7: # | B7: sector | C7: sector_short | D7: activity | E7: so | F7: ActFullCode | G7: modality_group | H7: needs | I7: recipient | J7: sp | K7: act_unit | L7: target_idp | M7: target_ndp | N7: target_overall | O7: cost_total | P7: targetPr_idp | Q7: targetPr_ndp | R7: targetPr_overall | S7: costPr_total
A8: 1 | B8: Education | C8: EDU | D8: Provision of social emotional learning support to children affected by war | E8: SO1 | F8: SP1_ED101_IK | G8: In-kind / Service | H8: Specific | I8: Individual | J8: SP1 | K8: Individual | L8: 80567 | M8: 111497 | N8: 192064 | O8: 8930976 | P8: 80566 | Q8: 111497 | R8: 192063 | S8: 8930976
A9: 2 | B9: Education | C9: EDU | D9: Support schools with emergency learning shelters and quick repair and rehabilitation of education institutions damaged by strikes | E9: SO1 | F9: SP1_ED102_IK | G9: In-kind / Service | H9: Specific | I9: Individual | J9: SP1 | K9: Individual | L9: 14520 | M9: 23908 | N9: 38428 | O9: 14602640 | P9: 14520 | Q9: 23908 | R9: 38428 | S9: 14602640
A10: 3 | B10: Education | C10: EDU | D10: Provision of rapid catch-up learning for children whose education was disrupted by the war | E10: SO2 | F10: SP1_ED203_IK | G10: In-kind / Service | H10: Specific | I10: Individual | J10: SP1 | K10: Individual | L10: 26857 | M10: 47777 | N10: 74634 | O10: 4104870 | P10: 26857 | Q10: 47777 | R10: 74634 | S10: 4104870
A11: 4 | B11: Education | C11: EDU | D11: Provision of rapid catch-up learning for children whose education was disrupted by the war | E11: SO2 | F11: SP2_ED203_IK | G11: In-kind / Service | H11: Specific | I11: Individual | J11: SP2 | K11: Individual | N11: 11093 | O11: 610129.86 | R11: 11093 | S11: 610115
A12: 5 | B12: Education | C12: EDU | D12: Provision of social emotional learning support to children affected by war | E12: SO1 | F12: SP3_ED101_IK | G12: In-kind / Service | H12: Specific | I12: Individual | J12: SP3 | K12: Individual | N12: 141506 | O12: 6580011.1 | R12: 82597 | S12: 3840781.4
A13: 6 | B13: Education | C13: EDU | D13: Support schools with emergency learning shelters and quick repair and rehabilitation of education institutions damaged by strikes | E13: SO1 | F13: SP3_ED102_IK | G13: In-kind / Service | H13: Specific | I13: Individual | J13: SP3 | K13: Individual | N13: 3538 | O13: 1344303.3 | R13: 2065 | S13: 784675.77
A14: 7 | B14: Education | C14: EDU | D14: Provision of rapid catch-up learning for children whose education was disrupted by the war | E14: SO2 | F14: SP3_ED203_IK | G14: In-kind / Service | H14: Specific | I14: Individual | J14: SP3 | K14: Individual | N14: 88441 | O14: 4864255.5 | R14: 51623 | S14: 2839287.3
A15: 8 | B15: Education | C15: EDU | D15: Provision of social emotional learning support to children affected by war | E15: SO1 | F15: SP4_ED101_IK | G15: In-kind / Service | H15: Specific | I15: Individual | J15: SP4 | K15: Individual | L15: 192725 | N15: 192725 | O15: 8961712.5 | P15: 111817 | R15: 111817 | S15: 5199490.5
A16: 9 | B16: Education | C16: EDU | D16: Provision of rapid catch-up learning for children whose education was disrupted by the war | E16: SO2 | F16: SP4_ED203_IK | G16: In-kind / Service | H16: Specific | I16: Individual | J16: SP4 | K16: Individual | L16: 151738 | N16: 151738 | O16: 8345590 | P16: 88037 | R16: 88037 | S16: 4842022.8
A17: 10 | B17: Food Security | C17: FSL_FS | D17: Distribution of recurrent emergency life-saving food assistance | E17: SO1 | F17: SP1_FS102_CV | G17: Cash / Voucher | H17: Generic | I17: Individual | J17: SP1 | K17: Individual | L17: 17173 | M17: 60118 | N17: 77291 | O17: 14254274 | P17: 17168 | Q17: 58634 | R17: 75802 | S17: 13979830
A18: 11 | B18: Food Security | C18: FSL_FS | D18: Distribution of recurrent emergency life-saving food assistance | E18: SO1 | F18: SP1_FS101_IK | G18: In-kind / Service | H18: Generic | I18: Individual | J18: SP1 | K18: Individual | L18: 154555 | M18: 541059 | N18: 695614 | O18: 1.1191737e+08 | P18: 154513 | Q18: 527707 | R18: 682220 | S18: 1.0976257e+08
A19: 12 | B19: Food Security | C19: FSL_FS | D19: Ready to Eat Kits (Survival Kit) | E19: SO1 | F19: SP1_FS104_IK | G19: In-kind / Service | H19: Generic | I19: Individual | J19: SP1 | K19: Individual | L19: 2348 | M19: 14868 | N19: 17216 | O19: 275457.23 | P19: 2348 | Q19: 14501 | R19: 16849 | S19: 269577.08
A20: 13 | B20: Food Security | C20: FSL_FS | D20: Hot Meals | E20: SO1 | F20: SP2_FS105_IK | G20: In-kind / Service | H20: Generic | I20: Individual | J20: SP2 | K20: Individual | N20: 126060 | O20: 756359.44 | R20: 126060 | S20: 756359.44
A21: 14 | B21: Food Security | C21: FSL_FS | D21: Ready to Eat Kits | E21: SO1 | F21: SP2_FS103_IK | G21: In-kind / Service | H21: Generic | I21: Individual | J21: SP2 | K21: Individual | N21: 126060 | O21: 1008479.2 | R21: 126060 | S21: 1008479.2
A22: 15 | B22: Food Security | C22: FSL_FS | D22: Hot Meals | E22: SO1 | F22: SP3_FS105_IK | G22: In-kind / Service | H22: Generic | I22: Individual | J22: SP3 | K22: Individual | N22: 377501 | O22: 2265007.1 | R22: 340124 | S22: 2040746.2
A23: 16 | B23: Food Security | C23: FSL_FS | D23: Ready to Eat Kits | E23: SO1 | F23: SP3_FS103_IK | G23: In-kind / Service | H23: Generic | I23: Individual | J23: SP3 | K23: Individual | N23: 330780 | O23: 2646241.9 | R23: 298029 | S23: 2384234.5
A24: 17 | B24: Food Security | C24: FSL_FS | D24: Distribution of recurrent emergency life-saving food assistance | E24: SO1 | F24: SP4_FS102_CV | G24: Cash / Voucher | H24: Generic | I24: Individual | J24: SP4 | K24: Individual | L24: 46000 | N24: 46000 | O24: 9691733.6 | P24: 34356 | R24: 34356 | S24: 7238376.6
A25: 18 | B25: Food Security | C25: FSL_FS | D25: Distribution of recurrent emergency life-saving food assistance | E25: SO1 | F25: SP4_FS101_IK | G25: In-kind / Service | H25: Generic | I25: Individual | J25: SP4 | K25: Individual | L25: 184001 | N25: 184001 | O25: 19872152 | P25: 137424 | R25: 137424 | S25: 14841733
A26: 19 | B26: Livelihoods | C26: FSL_LI | D26: Emergency Livestock Relocation | E26: SO1 | F26: SP2_LI105_CV | G26: Cash / Voucher | H26: Specific | I26: Individual | J26: SP2 | K26: Individual | N26: 16473 | O26: 13661496 | R26: 16473 | S26: 13661496
A27: 20 | B27: Livelihoods | C27: FSL_LI | D27: Household Income Protection Kit | E27: SO2 | F27: SP2_LI206_CV | G27: Cash / Voucher | H27: Specific | I27: Individual | J27: SP2 | K27: Individual | N27: 23527 | O27: 8306053.9 | R27: 23527 | S27: 8306053.9
A28: 21 | B28: Livelihoods | C28: FSL_LI | D28: Household Income Protection Kit | E28: SO2 | F28: SP3_LI206_CV | G28: Cash / Voucher | H28: Specific | I28: Individual | J28: SP3 | K28: Individual | N28: 29992 | O28: 10304745 | R28: 17317 | S28: 5949821.1
A29: 22 | B29: Livelihoods | C29: FSL_LI | D29: Emergency food production kit (crop) | E29: SO2 | F29: SP4_LI207_CV | G29: Cash / Voucher | H29: Specific | I29: Individual | J29: SP4 | K29: Individual | L29: 20242 | M29: 11462 | N29: 31704 | O29: 5634352.2 | P29: 13546 | Q29: 11012 | R29: 24558 | S29: 4364309.9
A30: 23 | B30: Livelihoods | C30: FSL_LI | D30: Emergency food production kit (crop) | E30: SO2 | F30: SP4_LI207_IK | G30: In-kind / Service | H30: Specific | I30: Individual | J30: SP4 | K30: Individual | L30: 50616 | M30: 45838 | N30: 96454 | O30: 17389158 | P30: 33872 | Q30: 44037 | R30: 77909 | S30: 14045798
A31: 24 | B31: Livelihoods | C31: FSL_LI | D31: Emergency food production kit (livestock and animal health) | E31: SO2 | F31: SP4_LI208_IK | G31: In-kind / Service | H31: Specific | I31: Individual | J31: SP4 | K31: Individual | L31: 12097 | M31: 13416 | N31: 25513 | O31: 3190819.5 | P31: 8095 | Q31: 12889 | R31: 20984 | S31: 2624411.4
A32: 25 | B32: Livelihoods | C32: FSL_LI | D32: Emergency food production kit (livestock and animal health) | E32: SO2 | F32: SP4_LI208_CV | G32: Cash / Voucher | H32: Specific | I32: Individual | J32: SP4 | K32: Individual | L32: 50123 | M32: 63520 | N32: 113643 | O32: 13988484 | P32: 33542 | Q32: 61024 | R32: 94566 | S32: 11639693
A33: 26 | B33: Livelihoods | C33: FSL_LI | D33: Emergency food production kit (mixed) | E33: SO2 | F33: SP4_LI209_IK | G33: In-kind / Service | H33: Specific | I33: Individual | J33: SP4 | K33: Individual | L33: 18865 | M33: 24220 | N33: 43085 | O33: 10262917 | P33: 12625 | Q33: 23268 | R33: 35893 | S33: 8549709.8
A34: 27 | B34: Livelihoods | C34: FSL_LI | D34: Emergency food production kit (mixed) | E34: SO2 | F34: SP4_LI209_CV | G34: Cash / Voucher | H34: Specific | I34: Individual | J34: SP4 | K34: Individual | L34: 66183 | M34: 44654 | N34: 110837 | O34: 25970941 | P34: 44289 | Q34: 42899 | R34: 87188 | S34: 20428742
A35: 28 | B35: Livelihoods | C35: FSL_LI | D35: Household Income Protection Kit | E35: SO2 | F35: SP4_LI206_CV | G35: Cash / Voucher | H35: Specific | I35: Individual | J35: SP4 | K35: Individual | L35: 50256 | M35: 35841 | N35: 86097 | O35: 29581806 | P35: 33631 | Q35: 34433 | R35: 68064 | S35: 23385911
A36: 29 | B36: Health | C36: HEA | D36: HE101 - Improve access to lifesaving integrated quality and integrated healthcare including MHPSS and nutrition | E36: SO1 | F36: SP1_HE101_IK | G36: In-kind / Service | H36: Specific | I36: Individual | J36: SP1 | K36: Individual | L36: 137605 | M36: 237037 | N36: 374642 | O36: 26457257 | P36: 137605 | Q36: 191363 | R36: 328968 | S36: 23231812
A37: 30 | B37: Health | C37: HEA | D37: HE102 - Provide financial support for health care related costs - cash or vouchers | E37: SO1 | F37: SP1_HE102_CV | G37: Cash / Voucher | H37: Specific | I37: Individual | J37: SP1 | K37: Individual | L37: 3023 | M37: 5970 | N37: 8993 | O37: 962241.15 | P37: 3023 | Q37: 4819 | R37: 7842 | S37: 839163.93
A38: 31 | B38: Health | C38: HEA | D38: HE103 - Support risk communication and community engagement and provision of Information Education and Communication (IEC) to improve health outcomes for patients, caregivers and health care providers | E38: SO1 | F38: SP1_HE103_IK | G38: In-kind / Service | H38: Specific | I38: Individual | J38: SP1 | K38: Individual | L38: 6372 | M38: 10440 | N38: 16812 | O38: 28592.702 | P38: 6372 | Q38: 8428 | R38: 14800 | S38: 25171.557
A39: 32 | B39: Health | C39: HEA | D39: HE104 - Procure, preposition and distribute essential medications, medical equipment and medical commodities to health facilities (PHC and Secondary/tertiary level) | E39: SO1 | F39: SP1_HE104_IK | G39: In-kind / Service | H39: Specific | I39: Individual | J39: SP1 | K39: Individual | L39: 213399 | M39: 481515 | N39: 694914 | O39: 20819623 | P39: 213399 | Q39: 388733 | R39: 602132 | S39: 18039918
A40: 33 | B40: Health | C40: HEA | D40: HE105 - Engage in capacity building for health care providers and first responders and other community members to improve their ability to respond to the needs of vulnerable populations | E40: SO1 | F40: SP1_HE105_IK | G40: In-kind / Service | H40: Specific | I40: Individual | J40: SP1 | K40: Individual | L40: 1501 | M40: 470 | N40: 1971 | O40: 843874.47 | P40: 1501 | Q40: 380 | R40: 1881 | S40: 805102.39
A41: 34 | B41: Health | C41: HEA | D41: HE201 - Provide support to improve readiness, preparedness, and response to all hazards, including outbreaks of disease | E41: SO2 | F41: SP1_HE206_IK | G41: In-kind / Service | H41: Generic | I41: Institution | J41: SP1 | K41: Individual | L41: 46651 | M41: 46659 | N41: 93310 | O41: 2595892.5 | P41: 46651 | Q41: 37669 | R41: 84320 | S41: 2345780.9
...

Sheet Overall by Cluster
A1: UKRAINE 2026 HNRP
A2: Overall PiN, Target and Prioritized Target by Cluster
A3: =ActivityList!A3 -> Release Date: 13 January 2026
D4: Internally Displaced People | AP4: War-Affected Non-Displaced | CB4: Overall
D5: # People in Need (IDP) | J5: Protection AoRs | M5: FSL AoRs | O5: Joint PiN | P5: # Target (IDP) | V5: Protection AoRs | Y5: FSL AoRs | AB5: Joint Target | AC5: # Prioritized Target (IDP) | AI5: Protection AoRs | AL5: FSL AoRs | AO5: Joint Target | AP5: # People in Need (WAND) | AV5: Protection AoRs | AY5: FSL AoRs | BA5: Joint PiN | BB5: # Target (WAND) | BH5: Protection AoRs | BK5: FSL AoRs | BN5: Joint Target | BO5: # Prioritized Target (WAND) | BU5: Protection AoRs | BX5: FSL AoRs | CA5: Joint Target | CB5: # People in Need (Overall) | CH5: Protection AoRs | CK5: FSL AoRs | CM5: Joint PiN | CN5: # Target (Overall) | CT5: Protection AoRs | CW5: FSL AoRs | CZ5: Joint Target | DA5: # Prioritized Target (Overall) | DG5: Protection AoRs | DJ5: FSL AoRs | DM5: Joint Target
A6: Geographical Zone | B6: Swath | C6: Code | D6: ED | E6: FS | F6: HE | G6: PR | H6: SN | I6: WA | J6: GP | K6: CP | L6: GB | M6: FD | N6: LI | P6: ED | Q6: FS | R6: HE | S6: PR | T6: SN | U6: WA | V6: GP | W6: CP | X6: GB | Y6: FD | Z6: LI | AA6: CW | AC6: ED | AD6: FS | AE6: HE | AF6: PR | AG6: SN | AH6: WA | AI6: GP | AJ6: CP | AK6: GB | AL6: FD | AM6: LI | AN6: CW | AP6: ED | AQ6: FS | AR6: HE | AS6: PR | AT6: SN | AU6: WA | AV6: GP | AW6: CP | AX6: GB | AY6: FD | AZ6: LI | BB6: ED | BC6: FS | BD6: HE | BE6: PR | BF6: SN | BG6: WA | BH6: GP | BI6: CP | BJ6: GB | BK6: FD | BL6: LI | BM6: CW | BO6: ED | BP6: FS | BQ6: HE | BR6: PR | BS6: SN | BT6: WA | BU6: GP | BV6: CP | BW6: GB | BX6: FD | BY6: LI | BZ6: CW | CB6: ED | CC6: FS | CD6: HE | CE6: PR | CF6: SN | CG6: WA | CH6: GP | CI6: CP | CJ6: GB | CK6: FD | CL6: LI | CN6: ED | CO6: FS | CP6: HE | CQ6: PR | CR6: SN | CS6: WA | CT6: GP | CU6: CP | CV6: GB | CW6: FD | CX6: LI | CY6: CW | DA6: ED | DB6: FS | DC6: HE | DD6: PR | DE6: SN | DF6: WA | DG6: GP | DH6: CP | DI6: GB | DJ6: FD | DK6: LI | DL6: CW
A7: geo_zone | B7: swath | C7: code | D7: spAll_idp_pin_ed | E7: spAll_idp_pin_fl | F7: spAll_idp_pin_he | G7: spAll_idp_pin_pr | H7: spAll_idp_pin_sn | I7: spAll_idp_pin_wa | J7: spAll_idp_pin_gp | K7: spAll_idp_pin_cp | L7: spAll_idp_pin_gb | M7: spAll_idp_pin_fs | N7: spAll_idp_pin_li | O7: spAll_idp_pin_adopted | P7: spAll_idp_target_ed | Q7: spAll_idp_target_fl | R7: spAll_idp_target_he | S7: spAll_idp_target_pr | T7: spAll_idp_target_sn | U7: spAll_idp_target_wa | V7: spAll_idp_target_gp | W7: spAll_idp_target_cp | X7: spAll_idp_target_gb | Y7: spAll_idp_target_fs | Z7: spAll_idp_target_li | AA7: spAll_idp_target_cw | AB7: spAll_idp_target_joint | AC7: spAll_idp_targetPr_ed | AD7: spAll_idp_targetPr_fl | AE7: spAll_idp_targetPr_he | AF7: spAll_idp_targetPr_pr | AG7: spAll_idp_targetPr_sn | AH7: spAll_idp_targetPr_wa | AI7: spAll_idp_targetPr_gp | AJ7: spAll_idp_targetPr_cp | AK7: spAll_idp_targetPr_gb | AL7: spAll_idp_targetPr_fs | AM7: spAll_idp_targetPr_li | AN7: spAll_idp_targetPr_cw | AO7: spAll_idp_targetPr_joint | AP7: spAll_ndp_pin_ed | AQ7: spAll_ndp_pin_fl | AR7: spAll_ndp_pin_he | AS7: spAll_ndp_pin_pr | AT7: spAll_ndp_pin_sn | AU7: spAll_ndp_pin_wa | AV7: spAll_ndp_pin_gp | AW7: spAll_ndp_pin_cp | AX7: spAll_ndp_pin_gb | AY7: spAll_ndp_pin_fs | AZ7: spAll_ndp_pin_li | BA7: spAll_ndp_pin_adopted | BB7: spAll_ndp_target_ed | BC7: spAll_ndp_target_fl | BD7: spAll_ndp_target_he | BE7: spAll_ndp_target_pr | BF7: spAll_ndp_target_sn | BG7: spAll_ndp_target_wa | BH7: spAll_ndp_target_gp | BI7: spAll_ndp_target_cp | BJ7: spAll_ndp_target_gb | BK7: spAll_ndp_target_fs | BL7: spAll_ndp_target_li | BM7: spAll_ndp_target_cw | BN7: spAll_ndp_target_joint | BO7: spAll_ndp_targetPr_ed | BP7: spAll_ndp_targetPr_fl | BQ7: spAll_ndp_targetPr_he | BR7: spAll_ndp_targetPr_pr | BS7: spAll_ndp_targetPr_sn | BT7: spAll_ndp_targetPr_wa | BU7: spAll_ndp_targetPr_gp | BV7: spAll_ndp_targetPr_cp | BW7: spAll_ndp_targetPr_gb | BX7: spAll_ndp_targetPr_fs | BY7: spAll_ndp_targetPr_li | BZ7: spAll_ndp_targetPr_cw | CA7: spAll_ndp_targetPr_joint | CB7: spAll_overall_pin_ed | CC7: spAll_overall_pin_fl | CD7: spAll_overall_pin_he | CE7: spAll_overall_pin_pr | CF7: spAll_overall_pin_sn | CG7: spAll_overall_pin_wa | CH7: spAll_overall_pin_gp | CI7: spAll_overall_pin_cp | CJ7: spAll_overall_pin_gb | CK7: spAll_overall_pin_fs | CL7: spAll_overall_pin_li | CM7: spAll_overall_pin_adopted | CN7: spAll_overall_target_ed | CO7: spAll_overall_target_fl | CP7: spAll_overall_target_he | CQ7: spAll_overall_target_pr | CR7: spAll_overall_target_sn | CS7: spAll_overall_target_wa | CT7: spAll_overall_target_gp | CU7: spAll_overall_target_cp | CV7: spAll_overall_target_gb | CW7: spAll_overall_target_fs | CX7: spAll_overall_target_li | CY7: spAll_overall_target_cw | CZ7: spAll_overall_target_joint | DA7: spAll_overall_targetPr_ed | DB7: spAll_overall_targetPr_fl | DC7: spAll_overall_targetPr_he | DD7: spAll_overall_targetPr_pr | DE7: spAll_overall_targetPr_sn | DF7: spAll_overall_targetPr_wa | DG7: spAll_overall_targetPr_gp | DH7: spAll_overall_targetPr_cp | DI7: spAll_overall_targetPr_gb | DJ7: spAll_overall_targetPr_fs | DK7: spAll_overall_targetPr_li | DL7: spAll_overall_targetPr_cw | DM7: spAll_overall_targetPr_joint
A8: GCA 0-20 km | B8: 0-20km | C8: UAGC_U20A | D8: 25705 | E8: 49022 | F8: 119279 | G8: 121128 | H8: 116780 | I8: 133730 | J8: 120312 | K8: 68716 | L8: 67782 | M8: 49022 | N8: 49022 | O8: 142420 | P8: 23136 | Q8: 49022 | R8: 88579 | S8: 90235 | T8: 93425 | U8: 133730 | V8: 90235 | W8: 39370 | X8: 3389 | Y8: 49022 | Z8: 10589 | AA8: 99278 | AB8: 137706 | AC8: 23136 | AD8: 49022 | AE8: 88579 | AF8: 90235 | AG8: 93425 | AH8: 133730 | AI8: 90235 | AJ8: 39370 | AK8: 3389 | AL8: 49022 | AM8: 10589 | AN8: 99278 | AO8: 137706 | AP8: 62304 | AQ8: 328817 | AR8: 856878 | AS8: 836056 | AT8: 827141 | AU8: 970508 | AV8: 836056 | AW8: 283388 | AX8: 478226 | AY8: 328817 | AZ8: 328817 | BA8: 1004983 | BB8: 56073 | BC8: 328817 | BD8: 436464 | BE8: 504240 | BF8: 452105 | BG8: 970508 | BH8: 504240 | BI8: 254460 | BJ8: 75636 | BK8: 328817 | BL8: 182126 | BM8: 544495 | BN8: 982830 | BO8: 56073 | BP8: 328817 | BQ8: 384116 | BR8: 504240 | BS8: 452105 | BT8: 970508 | BU8: 504240 | BV8: 254460 | BW8: 75636 | BX8: 328817 | BY8: 182126 | BZ8: 544495 | CA8: 982830 | CB8: 88009 | CC8: 377839 | CD8: 976157 | CE8: 957184 | CF8: 943921 | CG8: 1104238 | CH8: 956368 | CI8: 352104 | CJ8: 546008 | CK8: 377839 | CL8: 377839 | CM8: 1147403 | CN8: 79209 | CO8: 377839 | CP8: 525043 | CQ8: 594475 | CR8: 545530 | CS8: 1104238 | CT8: 594475 | CU8: 293830 | CV8: 79025 | CW8: 377839 | CX8: 192715 | CY8: 643773 | CZ8: 1120536 | DA8: 79209 | DB8: 377839 | DC8: 472695 | DD8: 594475 | DE8: 545530 | DF8: 1104238 | DG8: 594475 | DH8: 293830 | DI8: 79025 | DJ8: 377839 | DK8: 192715 | DL8: 643773 | DM8: 1120536
A9: GCA 21-50 km | B9: 20-50km | C9: UAGC_U50A | D9: 109967 | E9: 258749 | F9: 383749 | G9: 394874 | H9: 301187 | I9: 373618 | J9: 394874 | K9: 224186 | L9: 195004 | M9: 258749 | N9: 258749 | O9: 416154 | P9: 98971 | Q9: 250425 | R9: 319975 | S9: 296157 | T9: 235579 | U9: 352843 | V9: 296157 | W9: 128241 | X9: 97990 | Y9: 250393 | Z9: 114643 | AA9: 117319 | AB9: 366777 | AC9: 98971 | AD9: 250378 | AE9: 319975 | AF9: 296157 | AG9: 235579 | AH9: 352642 | AI9: 296157 | AJ9: 128241 | AK9: 97943 | AL9: 250346 | AM9: 114643 | AN9: 117065 | AO9: 366777 | AP9: 91342 | AQ9: 361628 | AR9: 1101659 | AS9: 1193210 | AT9: 997094 | AU9: 1239824 | AV9: 1193210 | AW9: 368486 | AX9: 466264 | AY9: 361628 | AZ9: 361628 | BA9: 1378554 | BB9: 79232 | BC9: 361628 | BD9: 466245 | BE9: 468750 | BF9: 319451 | BG9: 1058910 | BH9: 372983 | BI9: 301836 | BJ9: 211189 | BK9: 361628 | BL9: 109133 | BM9: 135137 | BN9: 1193605 | BO9: 79232 | BP9: 346288 | BQ9: 359407 | BR9: 468749 | BS9: 315978 | BT9: 1033223 | BU9: 372983 | BV9: 282274 | BW9: 204569 | BX9: 346288 | BY9: 99743 | BZ9: 129066 | CA9: 1180627 | CB9: 201309 | CC9: 620377 | CD9: 1485408 | CE9: 1588084 | CF9: 1298281 | CG9: 1613442 | CH9: 1588084 | CI9: 592672 | CJ9: 661268 | CK9: 620377 | CL9: 620377 | CM9: 1794708 | CN9: 178203 | CO9: 612053 | CP9: 786220 | CQ9: 764907 | CR9: 555030 | CS9: 1411753 | CT9: 669140 | CU9: 430077 | CV9: 309179 | CW9: 612021 | CX9: 223776 | CY9: 252456 | CZ9: 1560382 | DA9: 178203 | DB9: 596666 | DC9: 679382 | DD9: 764906 | DE9: 551557 | DF9: 1385865 | DG9: 669140 | DH9: 410515 | DI9: 302512 | DJ9: 596634 | DK9: 214386 | DL9: 246131 | DM9: 1547404
A10: GCA 51+ km | B10: 50+ | C10: UAGC_U51P | D10: 303146 | E10: 495429 | F10: 1518221 | G10: 1847162 | H10: 1207226 | I10: 1567847 | J10: 1844728 | K10: 878160 | L10: 629704 | M10: 495429 | N10: 495429 | O10: 1870245 | P10: 160213 | Q10: 255296 | R10: 102657 | S10: 634704 | T10: 91537 | U10: 417091 | V10: 595491 | W10: 290902 | X10: 129880 | Y10: 110306 | Z10: 146904 | AA10: 93271 | AB10: 705031 | AC10: 72083 | AD10: 94491.8 | AE10: 66134 | AF10: 505637 | AG10: 43384 | AH10: 123624 | AI10: 496317 | AJ10: 157109 | AK10: 66831 | AL10: 47570 | AM10: 56593 | AN10: 31456 | AO10: 563131 | AP10: 164313 | AQ10: 41078 | AR10: 0 | AS10: 1643127 | AT10: 1643127 | AU10: 1643127 | AV10: 1643127 | AW10: 575094 | AX10: 575094 | AY10: 41078 | AZ10: 41078 | BA10: 5048344.3 | BB10: 65726 | BC10: 41078 | BD10: 0 | BE10: 432427 | BF10: 228177 | BG10: 410782 | BH10: 164313 | BI10: 243467 | BJ10: 24647 | BK10: 41078 | BL10: 13930 | BM10: 67420 | BN10: 432427 | BO10: 13145 | BP10: 8215 | BQ10: 0 | BR10: 86485 | BS10: 45635 | BT10: 82156 | BU10: 32863 | BV10: 48693 | BW10: 4930 | BX10: 8215 | BY10: 2786 | BZ10: 13484 | CA10: 86485 | CB10: 467459 | CC10: 536507 | CD10: 1518221 | CE10: 3490289 | CF10: 2850353 | CG10: 3210974 | CH10: 3487855 | CI10: 1453254 | CJ10: 1204798 | CK10: 536507 | CL10: 536507 | CM10: 6918589.3 | CN10: 225939 | CO10: 296374 | CP10: 102657 | CQ10: 1067131 | CR10: 319714 | CS10: 827873 | CT10: 759804 | CU10: 534369 | CV10: 154527 | CW10: 151384 | CX10: 160834 | CY10: 160691 | CZ10: 1137458 | DA10: 85228 | DB10: 102706.8 | DC10: 66134 | DD10: 592122 | DE10: 89019 | DF10: 205780 | DG10: 529180 | DH10: 205802 | DI10: 71761 | DJ10: 55785 | DK10: 59379 | DL10: 44940 | DM10: 649616
A11: OT 0-20 km | B11: 0-20km | C11: UAOT_O20A | O11: 7414 | AB11: 4236 | AO11: 4236 | BA11: 224914 | BN11: 128460 | CA11: 128460 | CM11: 232328 | CZ11: 132696 | DM11: 132696
A12: OT 21-50 km | B12: 20-50km | C12: UAOT_O50A | O12: 10647 | AB12: 5182 | AO12: 5182 | BA12: 225310 | BN12: 155189 | CA12: 155189 | CM12: 235957 | CZ12: 160371 | DM12: 160371
A13: 51+ km (occupied after 2022) | B13: 50+ | C13: UAOT_O51N | O13: 15802 | AB13: 1507 | AO13: 1507 | BA13: 304427 | BN13: 3028 | CA13: 3028 | CM13: 320229 | CZ13: 4535 | DM13: 4535
A14: 51+ km (occupied before 2022) | B14: 50+ | C14: UAOT_O51O | O14: 9893 | AB14: 2028 | AO14: 406 | BA14: 190590 | BN14: 948 | CA14: 189 | CM14: 200483 | CZ14: 2976 | DM14: 595
A15: Total | O15: =SUBTOTAL(109,Overall[spAll_idp_pin_adopted]) -> 2472575 | AB15: =SUBTOTAL(109,Overall[spAll_idp_target_joint]) -> 1222467 | AO15: =SUBTOTAL(109,Overall[spAll_idp_targetPr_joint]) -> 1078945 | BA15: =SUBTOTAL(109,Overall[spAll_ndp_pin_adopted]) -> 8377122.3 | BN15: =SUBTOTAL(109,Overall[spAll_ndp_target_joint]) -> 2896487 | CA15: =SUBTOTAL(109,Overall[spAll_ndp_targetPr_joint]) -> 2536808 | CM15: =SUBTOTAL(109,Overall[spAll_overall_pin_adopted]) -> 10849697 | CZ15: =SUBTOTAL(109,Overall[spAll_overall_target_joint]) -> 4118954 | DM15: =SUBTOTAL(109,Overall[spAll_overall_targetPr_joint]) -> 3615753

Sheet Overall by SP and UoA
A1: UKRAINE 2026 HNRP
A2: Overall Affected, PiN, Target and Prioritized Target by Strategic Priority
A3: =ActivityList!A3 -> Release Date: 13 January 2026
M4: ed | N4: fs | O4: he | P4: pr | Q4: sn | R4: wa
A5: Oblast | C5: Analysis Zones | F5: Baseline | G5: # Affected Overall | M5: # People in Need (Individuals) | S5: Severity Phase | X5: # Target (Individuals) | AC5: # Prioritized Target (Individuals)
A6: Name (English) | B6: Pcode | C6: Geo Zone | D6: Swath | E6: Code | F6: Population | G6: SP1 | H6: SP2 | I6: SP3 | J6: SP4 | K6: WAND 50+ | L6: Overall | M6: SP1 | N6: SP2 | O6: SP3 | P6: SP4 | Q6: WAND 50+ | R6: Overall | S6: SP1 | T6: SP2 | U6: SP3 | V6: SP4 | W6: Overall | X6: SP1 | Y6: SP2 | Z6: SP3 | AA6: SP4 | AB6: Overall | AC6: SP1 | AD6: SP2 | AE6: SP3 | AF6: SP4 | AG6: Overall
A7: ADM1_EN | B7: ADM1_PCODE | C7: geo_zone | D7: swath | E7: UoA_code | F7: overall_all_total_joint | G7: overall_aff_sp1_joint | H7: overall_aff_sp2_joint | I7: overall_aff_sp3_joint | J7: overall_aff_sp4_joint | K7: overall_aff_sp5_joint | L7: overall_aff_total_joint | M7: overall_pin_sp1_joint | N7: overall_pin_sp2_joint | O7: overall_pin_sp3_joint | P7: overall_pin_sp4_joint | Q7: overall_pin_sp5_joint | R7: overall_pin_total_joint | S7: overall_sev_sp1_joint | T7: overall_sev_sp2_joint | U7: overall_sev_sp3_joint | V7: overall_sev_sp4_joint | W7: overall_sev_total_joint | X7: overall_target_sp1_joint | Y7: overall_target_sp2_joint | Z7: overall_target_sp3_joint | AA7: overall_target_sp4_joint | AB7: overall_target_total_joint | AC7: overall_targetPr_sp1_joint | AD7: overall_targetPr_sp2_joint | AE7: overall_targetPr_sp3_joint | AF7: overall_targetPr_sp4_joint | AG7: overall_targetPr_total_joint
A8: Vinnytska | B8: UA05 | C8: All oblast | D8: 50+ | E8: UA05_UALL | F8: 1346645 | G8: 0 | H8: 0 | I8: 0 | J8: 88646 | K8: 0 | L8: 0 | M8: 0 | N8: 0 | O8: 0 | P8: 71599 | Q8: 0 | R8: 0 | S8: 0 | T8: 0 | U8: 3 | V8: 3 | W8: 3 | X8: 0 | Y8: 0 | Z8: 0 | AA8: 34095 | AB8: 0 | AC8: 0 | AD8: 0 | AE8: 0 | AF8: 34095 | AG8: 0
A9: Volynska | B9: UA07 | C9: All oblast | D9: 50+ | E9: UA07_UALL | F9: 915568 | G9: 0 | H9: 0 | I9: 0 | J9: 31262 | K9: 0 | L9: 0 | M9: 0 | N9: 0 | O9: 0 | P9: 26453 | Q9: 0 | R9: 0 | S9: 0 | T9: 0 | U9: 3 | V9: 3 | W9: 3 | X9: 0 | Y9: 0 | Z9: 0 | AA9: 11761 | AB9: 0 | AC9: 0 | AD9: 0 | AE9: 0 | AF9: 11761 | AG9: 0
A10: Dnipropetrovska | B10: UA12 | C10: 0-20 km | D10: 0-20km | E10: UA12_U20A | F10: 228268 | G10: 228268 | H10: 0 | I10: 0 | J10: 228268 | K10: 0 | L10: 0 | M10: 210709 | N10: 0 | O10: 0 | P10: 89572 | Q10: 0 | R10: 0 | S10: 5 | T10: 4 | U10: 5 | V10: 5 | W10: 5 | X10: 210709 | Y10: 0 | Z10: 0 | AA10: 40036 | AB10: 0 | AC10: 210709 | AD10: 0 | AE10: 0 | AF10: 40036 | AG10: 0
A11: Dnipropetrovska | B11: UA12 | C11: 21-50 km | D11: 20-50km | E11: UA12_U50A | F11: 164650 | G11: 98942.748 | H11: 0 | I11: 0 | J11: 88538 | K11: 0 | L11: 0 | M11: 82212 | N11: 0 | O11: 0 | P11: 48204 | Q11: 0 | R11: 0 | S11: 4 | T11: 0 | U11: 4 | V11: 4 | W11: 4 | X11: 80620 | Y11: 0 | Z11: 0 | AA11: 36546 | AB11: 0 | AC11: 80620 | AD11: 0 | AE11: 0 | AF11: 36546 | AG11: 0
A12: Dnipropetrovska | B12: UA12 | C12: 51+ km | D12: 50+ | E12: UA12_U51P | F12: 2785796 | G12: 0 | H12: 0 | I12: 0 | J12: 325353 | K12: 0 | L12: 0 | M12: 0 | N12: 0 | O12: 0 | P12: 276793 | Q12: 0 | R12: 0 | S12: 0 | T12: 0 | U12: 3 | V12: 4 | W12: 4 | X12: 0 | Y12: 0 | Z12: 0 | AA12: 138397 | AB12: 0 | AC12: 0 | AD12: 0 | AE12: 0 | AF12: 138397 | AG12: 0
A13: Donetska | B13: UA14 | C13: 0-20 km | D13: 0-20km | E13: UA14_U20A | F13: 180210 | G13: 180210 | H13: 0 | I13: 0 | J13: 180210 | K13: 0 | L13: 0 | M13: 167637 | N13: 0 | O13: 0 | P13: 79143 | Q13: 0 | R13: 0 | S13: 5 | T13: 4 | U13: 5 | V13: 5 | W13: 5 | X13: 167637 | Y13: 0 | Z13: 0 | AA13: 32596 | AB13: 0 | AC13: 167637 | AD13: 0 | AE13: 0 | AF13: 32596 | AG13: 0
A14: Donetska | B14: UA14 | C14: 21-50 km | D14: 20-50km | E14: UA14_U50A | F14: 61456 | G14: 45700.32 | H14: 0 | I14: 0 | J14: 42803 | K14: 0 | L14: 0 | M14: 38016 | N14: 0 | O14: 0 | P14: 18019 | Q14: 0 | R14: 0 | S14: 5 | T14: 0 | U14: 4 | V14: 5 | W14: 5 | X14: 37090 | Y14: 0 | Z14: 0 | AA14: 15535 | AB14: 0 | AC14: 37090 | AD14: 0 | AE14: 0 | AF14: 15535 | AG14: 0
A15: Zhytomyrska | B15: UA18 | C15: All oblast | D15: 50+ | E15: UA18_UALL | F15: 1081427 | G15: 0 | H15: 0 | I15: 0 | J15: 53364 | K15: 0 | L15: 0 | M15: 0 | N15: 0 | O15: 0 | P15: 42407 | Q15: 0 | R15: 0 | S15: 0 | T15: 0 | U15: 3 | V15: 3 | W15: 3 | X15: 0 | Y15: 0 | Z15: 0 | AA15: 10107 | AB15: 0 | AC15: 0 | AD15: 0 | AE15: 0 | AF15: 2021 | AG15: 0
A16: Zakarpatska | B16: UA21 | C16: All oblast | D16: 50+ | E16: UA21_UALL | F16: 841388 | G16: 0 | H16: 0 | I16: 0 | J16: 59270 | K16: 0 | L16: 0 | M16: 0 | N16: 0 | O16: 0 | P16: 52751 | Q16: 0 | R16: 0 | S16: 0 | T16: 0 | U16: 3 | V16: 3 | W16: 3 | X16: 0 | Y16: 0 | Z16: 0 | AA16: 10702 | AB16: 0 | AC16: 0 | AD16: 0 | AE16: 0 | AF16: 2140 | AG16: 0
A17: Zaporizka | B17: UA23 | C17: 0-20 km | D17: 0-20km | E17: UA23_U20A | F17: 57720 | G17: 57720 | H17: 0 | I17: 0 | J17: 57720 | K17: 0 | L17: 0 | M17: 57720 | N17: 0 | O17: 0 | P17: 25078 | Q17: 0 | R17: 0 | S17: 5 | T17: 4 | U17: 5 | V17: 5 | W17: 5 | X17: 57720 | Y17: 0 | Z17: 0 | AA17: 11040 | AB17: 0 | AC17: 57720 | AD17: 0 | AE17: 0 | AF17: 11040 | AG17: 0
A18: Zaporizka | B18: UA23 | C18: 21-50 km (w/o Zaporizhzhia) | D18: 20-50km | E18: UA23_U50X | F18: 72784 | G18: 42291.226 | H18: 0 | I18: 0 | J18: 36140 | K18: 0 | L18: 0 | M18: 37016 | N18: 0 | O18: 0 | P18: 20859 | Q18: 0 | R18: 0 | S18: 4 | T18: 0 | U18: 4 | V18: 4 | W18: 4 | X18: 26257 | Y18: 0 | Z18: 0 | AA18: 14618 | AB18: 0 | AC18: 26257 | AD18: 0 | AE18: 0 | AF18: 14618 | AG18: 0
A19: Zaporizka | B19: UA23 | C19: 51+ km | D19: 50+ | E19: UA23_U51P | F19: 4512 | G19: 0 | H19: 0 | I19: 0 | J19: 1034 | K19: 0 | L19: 0 | M19: 0 | N19: 0 | O19: 0 | P19: 821 | Q19: 0 | R19: 0 | S19: 0 | T19: 0 | U19: 3 | V19: 4 | W19: 4 | X19: 0 | Y19: 0 | Z19: 0 | AA19: 290 | AB19: 0 | AC19: 0 | AD19: 0 | AE19: 0 | AF19: 290 | AG19: 0
... A58: GCA 51+ km | B58: UAGC | C58: 51+ km GCA | D58: 50+ | E58: UAGC_U51P | F58: 26727253 | G58: 0 | H58: 0 | I58: 1868838 | J58: 1910493 | K58: 6407207 | L58: 8543411 | M58: 0 | N58: 0 | O58: 1868838 | P58: 1644534 | Q58: 5048344.3 | R58: 6918589.3 | S58: 0 | T58: 0 | U58: 3 | V58: 0 | W58: 0 | X58: 0 | Y58: 0 | Z58: 491828 | AA58: 645630 | AB58: 1137458 | AC58: 0 | AD58: 0 | AE58: 98365 | AF58: 551251 | AG58: 649616
A59: Total | F59: =SUM(F8:F55) -> 31928545 | G59: =SUM(G8:G55) -> 3449506.2 | H59: =SUBTOTAL(109,overall_total[overall_aff_sp2_joint]) -> 504240 | I59: =SUBTOTAL(109,overall_total[overall_aff_sp3_joint]) -> 2735911 | J59: =SUM(J8:J55) -> 5248964 | K59: =SUBTOTAL(109,overall_total[overall_aff_sp5_joint]) -> 6902224 | L59: =SUBTOTAL(109,overall_total[overall_aff_total_joint]) -> 12811238 | M59: =SUM(M8:M55) -> 3112787 | N59: =SUBTOTAL(109,overall_total[overall_pin_sp2_joint]) -> 504240 | O59: =SUBTOTAL(109,overall_total[overall_pin_sp3_joint]) -> 2735910 | P59: =SUM(P8:P55) -> 2672383 | Q59: =SUBTOTAL(109,overall_total[overall_pin_sp5_joint]) -> 5543361.3 | R59: =SUBTOTAL(109,overall_total[overall_pin_total_joint]) -> 10849697 | X59: =SUM(X8:X55) -> 2714052 | Y59: =SUBTOTAL(109,overall_total[overall_target_sp2_joint]) -> 504240 | Z59: =SUBTOTAL(109,overall_total[overall_target_sp3_joint]) -> 928780 | AA59: =SUM(AA8:AA55) -> 1081961 | AB59: =SUBTOTAL(109,overall_total[overall_target_total_joint]) -> 4118954 | AC59: =SUM(AC8:AC55) -> 2710465 | AD59: =SUBTOTAL(109,overall_total[overall_targetPr_sp2_joint]) -> 504240 | AE59: =SUBTOTAL(109,overall_total[overall_targetPr_sp3_joint]) -> 534519 | AF59: =SUM(AF8:AF55) -> 976609 | AG59: =SUBTOTAL(109,overall_total[overall_targetPr_total_joint]) -> 3615753
F61: Cells shaded in yellow are aggregated values that are repetative of other records/zones in the table.

Sheet IDPs
A1: UKRAINE 2026 HNRP
A2: Internally-Displaced People Affected, PiN, Target and Prioritized Target by Strategic Priority
A3: =ActivityList!A3 -> Release Date: 13 January 2026
L4: ed | M4: fs | N4: he | O4: pr | P4: wa
A5: Oblast | C5: Analysis Zones | F5: Baseline | G5: # Affected IDPs | L5: # People in Need (Individuals) | Q5: Severity Phase | V5: # Target (Individuals) | AA5: # Prioritized Target (Individuals)
A6: Name (English) | B6: Pcode | C6: Geo Zone | D6: Swath | E6: Code | F6: IDPs | G6: SP1 | H6: SP2 | I6: SP3 | J6: SP4 | K6: Overall | L6: SP1 | M6: SP2 | N6: SP3 | O6: SP4 | P6: Overall | Q6: SP1 | R6: SP2 | S6: SP3 | T6: SP4 | U6: Overall | V6: SP1 | W6: SP2 | X6: SP3 | Y6: SP4 | Z6: Overall | AA6: SP1 | AB6: SP2 | AC6: SP3 | AD6: SP4 | AE6: Overall
A7: ADM1_EN | B7: ADM1_PCODE | C7: geo_zone | D7: swath | E7: UoA_code | F7: idp_all_total_joint | G7: idp_aff_sp1_joint | H7: idp_aff_sp2_joint | I7: idp_aff_sp3_joint | J7: idp_aff_sp4_joint | K7: idp_aff_total_joint | L7: idp_pin_sp1_joint | M7: idp_pin_sp2_joint | N7: idp_pin_sp3_joint | O7: idp_pin_sp4_joint | P7: idp_pin_total_joint | Q7: idp_sev_sp1_joint | R7: idp_sev_sp2_joint | S7: idp_sev_sp3_joint | T7: idp_sev_sp4_joint | U7: idp_sev_total_joint | V7: idp_target_sp1_joint | W7: idp_target_sp2_joint | X7: idp_target_sp3_joint | Y7: idp_target_sp4_joint | Z7: idp_target_total_joint | AA7: idp_targetPr_sp1_joint | AB7: idp_targetPr_sp2_joint | AC7: idp_targetPr_sp3_joint | AD7: idp_targetPr_sp4_joint | AE7: idp_targetPr_total_joint
A8: Vinnytska | B8: UA05 | C8: All oblast | D8: 50+ | E8: UA05_UALL | F8: 124404 | G8: 0 | H8: 0 | I8: 0 | J8: 88646 | K8: 0 | L8: 0 | M8: 0 | N8: 0 | O8: 71599 | Q8: 0 | R8: 0 | S8: 3 | T8: 3 | U8: 3 | V8: 0 | W8: 0 | X8: 0 | Y8: 34095 | Z8: 0 | AA8: 0 | AD8: 34095
A9: Volynska | B9: UA07 | C9: All oblast | D9: 50+ | E9: UA07_UALL | F9: 44950 | G9: 0 | H9: 0 | I9: 0 | J9: 31262 | K9: 0 | L9: 0 | M9: 0 | N9: 0 | O9: 26453 | P9: 0 | Q9: 0 | R9: 0 | S9: 3 | T9: 3 | U9: 3 | V9: 0 | W9: 0 | X9: 0 | Y9: 11761 | Z9: 0 | AA9: 0 | AD9: 11761
A10: Dnipropetrovska | B10: UA12 | C10: 0-20 km | D10: 0-20km | E10: UA12_U20A | F10: 23346 | G10: 23346 | H10: 0 | I10: 0 | J10: 23346 | K10: 0 | L10: 21550 | M10: 0 | N10: 0 | O10: 9161 | P10: 0 | Q10: 5 | R10: 4 | S10: 5 | T10: 5 | U10: 5 | V10: 21550 | W10: 0 | X10: 0 | Y10: 1745 | Z10: 0 | AA10: 21550 | AD10: 1745
A11: Dnipropetrovska | B11: UA12 | C11: 21-50 km | D11: 20-50km | E11: UA12_U50A | F11: 37607 | G11: 37607 | H11: 0 | I11: 0 | J11: 27202 | K11: 0 | L11: 32235 | M11: 0 | N11: 0 | O11: 25648 | P11: 0 | Q11: 4 | R11: 0 | S11: 4 | T11: 4 | U11: 4 | V11: 30643 | W11: 0 | X11: 0 | Y11: 13990 | Z11: 0 | AA11: 30643 | AD11: 13990
A12: Dnipropetrovska | B12: UA12 | C12: 51+ km | D12: 50+ | E12: UA12_U51P | F12: 456409 | G12: 0 | H12: 0 | I12: 0 | J12: 325353 | K12: 0 | L12: 0 | M12: 0 | N12: 0 | O12: 276793 | P12: 0 | Q12: 0 | R12: 0 | S12: 3 | T12: 4 | U12: 4 | V12: 0 | W12: 0 | X12: 0 | Y12: 138397 | Z12: 0 | AA12: 0 | AD12: 138397
A13: Donetska | B13: UA14 | C13: 0-20 km | D13: 0-20km | E13: UA14_U20A | F13: 28205 | G13: 28205 | H13: 0 | I13: 0 | J13: 28205 | K13: 0 | L13: 26237 | M13: 0 | N13: 0 | O13: 12387 | P13: 0 | Q13: 5 | R13: 4 | S13: 5 | T13: 5 | U13: 5 | V13: 26237 | W13: 0 | X13: 0 | Y13: 2252 | Z13: 0 | AA13: 26237 | AD13: 2252
A14: Donetska | B14: UA14 | C14: 21-50 km | D14: 20-50km | E14: UA14_U50A | F14: 10472 | G14: 10472 | H14: 0 | I14: 0 | J14: 7575 | K14: 0 | L14: 9425 | M14: 0 | N14: 0 | O14: 7236 | P14: 0 | Q14: 5 | R14: 0 | S14: 4 | T14: 5 | U14: 5 | V14: 8499 | W14: 0 | X14: 0 | Y14: 4752 | Z14: 0 | AA14: 8499 | AD14: 4752
A15: Zhytomyrska | B15: UA18 | C15: All oblast | D15: 50+ | E15: UA18_UALL | F15: 80718 | G15: 0 | H15: 0 | I15: 0 | J15: 53364 | K15: 0 | L15: 0 | M15: 0 | N15: 0 | O15: 42407 | P15: 0 | Q15: 0 | R15: 0 | S15: 3 | T15: 3 | U15: 3 | V15: 0 | W15: 0 | X15: 0 | Y15: 10107 | Z15: 0 | AA15: 0 | AD15: 2021
A16: Zakarpatska | B16: UA21 | C16: All oblast | D16: 50+ | E16: UA21_UALL | F16: 85221 | G16: 0 | H16: 0 | I16: 0 | J16: 59270 | K16: 0 | L16: 0 | M16: 0 | N16: 0 | O16: 52751 | P16: 0 | Q16: 0 | R16: 0 | S16: 3 | T16: 3 | U16: 3 | V16: 0 | W16: 0 | X16: 0 | Y16: 10702 | Z16: 0 | AA16: 0 | AD16: 2140
A17: Zaporizka | B17: UA23 | C17: 0-20 km | D17: 0-20km | E17: UA23_U20A | F17: 7270 | G17: 7270 | H17: 0 | I17: 0 | J17: 7270 | K17: 0 | L17: 7270 | M17: 0 | N17: 0 | O17: 3159 | P17: 0 | Q17: 5 | R17: 4 | S17: 5 | T17: 5 | U17: 5 | V17: 7270 | W17: 0 | X17: 0 | Y17: 602 | Z17: 0 | AA17: 7270 | AD17: 602
A18: Zaporizka | B18: UA23 | C18: 21-50 km (w/o Zaporizhzhia) | D18: 20-50km | E18: UA23_U50X | F18: 22234 | G18: 22234 | H18: 0 | I18: 0 | J18: 16083 | K18: 0 | L18: 18964 | M18: 0 | N18: 0 | O18: 14621 | P18: 0 | Q18: 4 | R18: 0 | S18: 4 | T18: 4 | U18: 4 | V18: 14223 | W18: 0 | X18: 0 | Y18: 8380 | Z18: 0 | AA18: 14223 | AD18: 8380
A19: Zaporizka | B19: UA23 | C19: 51+ km | D19: 50+ | E19: UA23_U51P | F19: 1450 | G19: 0 | H19: 0 | I19: 0 | J19: 1034 | K19: 0 | L19: 0 | M19: 0 | N19: 0 | O19: 821 | P19: 0 | Q19: 0 | R19: 0 | S19: 3 | T19: 4 | U19: 4 | V19: 0 | W19: 0 | X19: 0 | Y19: 290 | Z19: 0 | AA19: 0 | AD19: 290
A20: Zaporizka | B20: UA23 | C20: Zaporizhzhia city | D20: 20-50km | E20: UA23_UCAP | F20: 131221 | G20: 131221 | H20: 0 | I20: 0 | J20: 94917 | K20: 0 | L20: 107076 | M20: 0 | N20: 0 | O20: 78781 | P20: 0 | Q20: 4 | R20: 0 | S20: 4 | T20: 4 | U20: 4 | V20: 81443 | W20: 0 | X20: 0 | Y20: 46471 | Z20: 0 | AA20: 81443 | AD20: 46471
... A51: Kyiv | B51: UA80 | C51: All oblast | D51: 50+ | E51: UA80_UALL | F51: 359687 | G51: 0 | H51: 0 | I51: 0 | J51: 213148 | K51: 0 | L51: 0 | M51: 0 | N51: 0 | O51: 184996 | P51: 0 | Q51: 0 | R51: 0 | S51: 3 | T51: 3 | U51: 3 | V51: 0 | W51: 0 | X51: 0 | Y51: 42875 | Z51: 0 | AA51: 0 | AD51: 11453
A52: OT | B52: UAOT | C52: OT 0-20 km | D52: 0-20km | E52: UAOT_O20A | F52: 7414 | G52: 7414 | H52: 0 | I52: 495 | J52: 7414 | K52: 7414 | L52: 7414 | M52: 0 | N52: 495 | O52: 7414 | P52: 7414 | Q52: 5 | R52: 0 | S52: 5 | T52: 5 | U52: 5 | V52: 4236 | W52: 0 | X52: 248 | Y52: 1207 | Z52: 4236 | AA52: 4236 | AC52: 248 | AD52: 1207 | AE52: 4236
A53: OT | B53: UAOT | C53: OT 21-50 km | D53: 20-50km | E53: UAOT_O50A | F53: 10647 | G53: 10647 | H53: 0 | I53: 306 | J53: 10647 | K53: 10647 | L53: 10647 | M53: 0 | N53: 306 | O53: 10647 | P53: 10647 | Q53: 4 | R53: 0 | S53: 4 | T53: 4 | U53: 4 | V53: 5182 | W53: 0 | X53: 153 | Y53: 1734 | Z53: 5182 | AA53: 5182 | AC53: 153 | AD53: 1734 | AE53: 5182
A54: OT | B54: UAOT | C54: 51+ km (occupied after 2022) | D54: 50+ | E54: UAOT_O51N | F54: 15802 | G54: 0 | H54: 0 | I54: 314 | J54: 15802 | K54: 15802 | L54: 0 | M54: 0 | N54: 314 | O54: 15802 | P54: 15802 | Q54: 0 | R54: 0 | S54: 4 | T54: 4 | U54: 4 | V54: 0 | W54: 0 | X54: 157 | Y54: 1350 | Z54: 1507 | AA54: 0 | AC54: 157 | AD54: 1350 | AE54: 1507
A55: OT | B55: UAOT | C55: 51+ km (occupied before 2022) | D55: 50+ | E55: UAOT_O51O | F55: 9893 | G55: 0 | H55: 0 | I55: 197 | J55: 9893 | K55: 9893 | L55: 0 | M55: 0 | N55: 197 | O55: 9893 | P55: 9893 | Q55: 0 | R55: 0 | S55: 3 | T55: 3 | U55: 3 | V55: 0 | W55: 0 | X55: 49 | Y55: 1979 | Z55: 2028 | AA55: 0 | AC55: 10 | AD55: 396 | AE55: 406
A56: GCA 0-20 km | B56: UAGC | C56: 0-20 km GCA | D56: 0-20km | E56: UAGC_U20A | F56: 153755 | G56: 153755 | H56: 504240 | I56: 60464 | J56: 153755 | K56: 153755 | L56: 142420 | M56: 504240 | N56: 60464 | O56: 49022 | P56: 142420 | Q56: 0 | R56: 4 | S56: 5 | T56: 0 | U56: 0 | V56: 137706 | W56: 504240 | X56: 30232 | Y56: 9564 | Z56: 137706 | AA56: 137706 | AB56: 504240 | AC56: 30232 | AD56: 9564 | AE56: 137706
A57: GCA 21-50 km | B57: UAGC | C57: 21-50 km GCA | D57: 20-50km | E57: UAGC_U50A | F57: 494663 | G57: 494663 | H57: 0 | I57: 48072 | J57: 357932 | K57: 494663 | L57: 416154 | M57: 0 | N57: 48072 | O57: 319028 | P57: 416154 | Q57: 0 | R57: 0 | S57: 4 | T57: 0 | U57: 0 | V57: 366777 | W57: 0 | X57: 24649 | Y57: 181546 | Z57: 366777 | AA57: 366777 | AC57: 24650 | AD57: 181546 | AE57: 366777
A58: GCA 51+ km | B58: UAGC | C58: 51+ km GCA | D58: 50+ | E58: UAGC_U51P | F58: 2845667 | G58: 0 | H58: 0 | I58: 225711 | J58: 1910493 | K58: 2136204 | L58: 0 | M58: 0 | N58: 225711 | O58: 1644534 | P58: 1870245 | Q58: 0 | R58: 0 | S58: 3 | T58: 0 | U58: 0 | V58: 0 | W58: 0 | X58: 59401 | Y58: 645630 | Z58: 705031 | AA58: 0 | AC58: 11880 | AD58: 551251 | AE58: 563131
A59: Total | F59: =SUM(F8:F55) -> 3537841 | G59: =SUM(G8:G55) -> 666479 | H59: =SUBTOTAL(109,idp_total[idp_aff_sp2_joint]) -> 504240 | I59: =SUBTOTAL(109,idp_total[idp_aff_sp3_joint]) -> 335559 | J59: =SUM(J8:J55) -> 2465936 | K59: =SUBTOTAL(109,idp_total[idp_aff_total_joint]) -> 2828378 | L59: =SUM(L8:L55) -> 576635 | M59: =SUBTOTAL(109,idp_total[idp_pin_sp2_joint]) -> 504240 | N59: =SUBTOTAL(109,idp_total[idp_pin_sp3_joint]) -> 335559 | O59: =SUM(O8:O55) -> 2056340 | P59: =SUBTOTAL(109,idp_total[idp_pin_total_joint]) -> 2472575 | V59: =SUM(V8:V55) -> 513901 | W59: =SUBTOTAL(109,idp_total[idp_target_sp2_joint]) -> 504240 | X59: =SUBTOTAL(109,idp_total[idp_target_sp3_joint]) -> 114889 | Y59: =SUM(Y8:Y55) -> 843010 | Z59: =SUBTOTAL(109,idp_total[idp_target_total_joint]) -> 1222467 | AA59: =SUM(AA8:AA55) -> 513901 | AB59: =SUBTOTAL(109,idp_total[idp_targetPr_sp2_joint]) -> 504240 | AC59: =SUBTOTAL(109,idp_total[idp_targetPr_sp3_joint]) -> 67330 | AD59: =SUM(AD8:AD55) -> 747048 | AE59: =SUBTOTAL(109,idp_total[idp_targetPr_total_joint]) -> 1078945
F61: Cells shaded in yellow are aggregated values that are repetative of other records/zones in the table.

Sheet WAND
A1: UKRAINE 2026 HNRP
A2: War-Affected Non-Displaced (WAND) People Affected, PiN, Target and Prioritized Target by Strategic Priority
A3: =ActivityList!A3 -> Release Date: 13 January 2026
M4: ed | N4: fs | O4: he | P4: pr | Q4: sn | R4: wa
A5: Oblast | C5: Analysis Zones | F5: Baseline | G5: # Affected WAND | M5: # People in Need (Individuals) | S5: Severity Phase | X5: # Target (Individuals) | AC5: # Prioritized Target (Individuals)
A6: Name (English) | B6: Pcode | C6: Geo Zone | D6: Swath | E6: Code | F6: Non-displaced People | G6: SP1 | H6: SP2 | I6: SP3 | J6: SP4 | K6: WAND 50+ | L6: Overall | M6: SP1 | N6: SP2 | O6: SP3 | P6: SP4 | Q6: WAND 50+ | R6: Overall | S6: SP1 | T6: SP2 | U6: SP3 | V6: SP4 | W6: Overall | X6: SP1 | Y6: SP2 | Z6: SP3 | AA6: SP4 | AB6: Overall | AC6: SP1 | AD6: SP2 | AE6: SP3 | AF6: SP4 | AG6: Overall
A7: ADM1_EN | B7: ADM1_PCODE | C7: geo_zone | D7: swath | E7: UoA_code | F7: ndp_all_total_joint | G7: ndp_aff_sp1_joint | H7: ndp_aff_sp2_joint | I7: ndp_aff_sp3_joint | J7: ndp_aff_sp4_joint | K7: ndp_aff_sp5_joint | L7: ndp_aff_total_joint | M7: ndp_pin_sp1_joint | N7: ndp_pin_sp2_joint | O7: ndp_pin_sp3_joint | P7: ndp_pin_sp4_joint | Q7: ndp_pin_sp5_joint | R7: ndp_pin_total_joint | S7: ndp_sev_sp1_joint | T7: ndp_sev_sp2_joint | U7: ndp_sev_sp3_joint | V7: ndp_sev_sp4_joint | W7: ndp_sev_total_joint | X7: ndp_target_sp1_joint | Y7: ndp_target_sp2_joint | Z7: ndp_target_sp3_joint | AA7: ndp_target_sp4_joint | AB7: ndp_target_total_joint | AC7: ndp_targetPr_sp1_joint | AD7: ndp_targetPr_sp2_joint | AE7: ndp_targetPr_sp3_joint | AF7: ndp_targetPr_sp4_joint | AG7: ndp_targetPr_total_joint
A8: Vinnytska | B8: UA05 | C8: All oblast | D8: 50+ | E8: UA05_UALL | F8: 1222241 | G8: 0 | H8: 0 | I8: 0 | J8: 0 | K8: 0 | L8: 0 | M8: 0 | N8: 0 | O8: 0 | P8: 0 | Q8: 0 | R8: 0 | S8: 0 | T8: - | U8: 3 | V8: 0 | W8: 3 | X8: 0 | Y8: 0 | Z8: 0 | AA8: 0 | AB8: 0 | AC8: 0 | AF8: 0
A9: Volynska | B9: UA07 | C9: All oblast | D9: 50+ | E9: UA07_UALL | F9: 870618 | G9: 0 | H9: 0 | I9: 0 | J9: 0 | K9: 0 | L9: 0 | M9: 0 | N9: 0 | O9: 0 | P9: 0 | Q9: 0 | R9: 0 | S9: 0 | T9: - | U9: 3 | V9: 0 | W9: 3 | X9: 0 | Y9: 0 | Z9: 0 | AA9: 0 | AB9: 0 | AC9: 0 | AF9: 0
A10: Dnipropetrovska | B10: UA12 | C10: 0-20 km | D10: 0-20km | E10: UA12_U20A | F10: 204922 | G10: 204922 | H10: 0 | I10: 0 | J10: 204922 | K10: 0 | L10: 0 | M10: 189159 | N10: 0 | O10: 0 | P10: 80411 | Q10: 0 | R10: 0 | S10: 5 | T10: - | U10: 5 | V10: 5 | W10: 5 | X10: 189159 | Y10: 0 | Z10: 0 | AA10: 38291 | AB10: 0 | AC10: 189159 | AF10: 38291
A11: Dnipropetrovska | B11: UA12 | C11: 21-50 km | D11: 20-50km | E11: UA12_U50A | F11: 127043 | G11: 61335.748 | H11: 0 | I11: 0 | J11: 61336 | K11: 0 | L11: 0 | M11: 49977 | N11: 0 | O11: 0 | P11: 22556 | Q11: 0 | R11: 0 | S11: 4 | T11: - | U11: 4 | V11: 4 | W11: 4 | X11: 49977 | Y11: 0 | Z11: 0 | AA11: 22556 | AB11: 0 | AC11: 49977 | AF11: 22556
A12: Dnipropetrovska | B12: UA12 | C12: 51+ km | D12: 50+ | E12: UA12_U51P | F12: 2329387 | G12: 0 | H12: 0 | I12: 0 | J12: 0 | K12: 0 | L12: 0 | M12: 0 | N12: 0 | O12: 0 | P12: 0 | Q12: 0 | R12: 0 | S12: 0 | T12: - | U12: 3 | V12: 0 | W12: 3 | X12: 0 | Y12: 0 | Z12: 0 | AA12: 0 | AB12: 0 | AC12: 0 | AF12: 0
A13: Donetska | B13: UA14 | C13: 0-20 km | D13: 0-20km | E13: UA14_U20A | F13: 152005 | G13: 152005 | H13: 0 | I13: 0 | J13: 152005 | K13: 0 | L13: 0 | M13: 141400 | N13: 0 | O13: 0 | P13: 66756 | Q13: 0 | R13: 0 | S13: 5 | T13: - | U13: 5 | V13: 5 | W13: 5 | X13: 141400 | Y13: 0 | Z13: 0 | AA13: 30344 | AB13: 0 | AC13: 141400 | AF13: 30344
A14: Donetska | B14: UA14 | C14: 21-50 km | D14: 20-50km | E14: UA14_U50A | F14: 50984 | G14: 35228.32 | H14: 0 | I14: 0 | J14: 35228 | K14: 0 | L14: 0 | M14: 28591 | N14: 0 | O14: 0 | P14: 10783 | Q14: 0 | R14: 0 | S14: 5 | T14: - | U14: 4 | V14: 5 | W14: 5 | X14: 28591 | Y14: 0 | Z14: 0 | AA14: 10783 | AB14: 0 | AC14: 28591 | AF14: 10783
A15: Zhytomyrska | B15: UA18 | C15: All oblast | D15: 50+ | E15: UA18_UALL | F15: 1000709 | G15: 0 | H15: 0 | I15: 0 | J15: 0 | K15: 0 | L15: 0 | M15: 0 | N15: 0 | O15: 0 | P15: 0 | Q15: 0 | R15: 0 | S15: 0 | T15: - | U15: 3 | V15: 0 | W15: 3 | X15: 0 | Y15: 0 | Z15: 0 | AA15: 0 | AB15: 0 | AC15: 0 | AF15: 0
A16: Zakarpatska | B16: UA21 | C16: All oblast | D16: 50+ | E16: UA21_UALL | F16: 756167 | G16: 0 | H16: 0 | I16: 0 | J16: 0 | K16: 0 | L16: 0 | M16: 0 | N16: 0 | O16: 0 | P16: 0 | Q16: 0 | R16: 0 | S16: 0 | T16: - | U16: 3 | V16: 0 | W16: 3 | X16: 0 | Y16: 0 | Z16: 0 | AA16: 0 | AB16: 0 | AC16: 0 | AF16: 0
A17: Zaporizka | B17: UA23 | C17: 0-20 km | D17: 0-20km | E17: UA23_U20A | F17: 50450 | G17: 50450 | H17: 0 | I17: 0 | J17: 50450 | K17: 0 | L17: 0 | M17: 50450 | N17: 0 | O17: 0 | P17: 21919 | Q17: 0 | R17: 0 | S17: 5 | T17: - | U17: 5 | V17: 5 | W17: 5 | X17: 50450 | Y17: 0 | Z17: 0 | AA17: 10438 | AB17: 0 | AC17: 50450 | AF17: 10438
A18: Zaporizka | B18: UA23 | C18: 21-50 km (w/o Zaporizhzhia) | D18: 20-50km | E18: UA23_U50X | F18: 50550 | G18: 20057.226 | H18: 0 | I18: 0 | J18: 20057 | K18: 0 | L18: 0 | M18: 18052 | N18: 0 | O18: 0 | P18: 6238 | Q18: 0 | R18: 0 | S18: 4 | T18: - | U18: 4 | V18: 4 | W18: 4 | X18: 12034 | Y18: 0 | Z18: 0 | AA18: 6238 | AB18: 0 | AC18: 12034 | AF18: 6238
A19: Zaporizka | B19: UA23 | C19: 51+ km | D19: 50+ | E19: UA23_U51P | F19: 3062 | G19: 0 | H19: 0 | I19: 0 | J19: 0 | K19: 0 | L19: 0 | M19: 0 | N19: 0 | O19: 0 | P19: 0 | Q19: 0 | R19: 0 | S19: 0 | T19: - | U19: 3 | V19: 0 | W19: 3 | X19: 0 | Y19: 0 | Z19: 0 | AA19: 0 | AB19: 0 | AC19: 0 | AF19: 0
... A51: Kyiv | B51: UA80 | C51: All oblast | D51: 50+ | E51: UA80_UALL | F51: 3034506 | G51: 0 | H51: 0 | I51: 0 | J51: 0 | K51: 0 | L51: 0 | M51: 0 | N51: 0 | O51: 0 | P51: 0 | Q51: 0 | R51: 0 | S51: 0 | T51: - | U51: 3 | V51: 0 | W51: 3 | X51: 0 | Y51: 0 | Z51: 0 | AA51: 0 | AB51: 0 | AC51: 0 | AF51: 0
A52: OT | B52: UAOT | C52: OT 0-20 km | D52: 0-20km | E52: UAOT_O20A | F52: 224914 | G52: 224914 | H52: 0 | I52: 15029 | J52: 224914 | K52: 0 | L52: 224914 | M52: 224914 | N52: 0 | O52: 15029 | P52: 0 | Q52: 0 | R52: 224914 | S52: 5 | T52: - | U52: 5 | V52: 5 | W52: 5 | X52: 128460 | Y52: 0 | Z52: 7514 | AA52: 0 | AB52: 128460 | AC52: 128460 | AE52: 7514 | AF52: 0 | AG52: 128460
A53: OT | B53: UAOT | C53: OT 21-50 km | D53: 20-50km | E53: UAOT_O50A | F53: 225310 | G53: 225310 | H53: 0 | I53: 6485 | J53: 225310 | K53: 0 | L53: 225310 | M53: 225310 | N53: 0 | O53: 6485 | P53: 0 | Q53: 0 | R53: 225310 | S53: 4 | T53: - | U53: 4 | V53: 4 | W53: 4 | X53: 151946 | Y53: 0 | Z53: 3243 | AA53: 0 | AB53: 155189 | AC53: 151946 | AE53: 3243 | AF53: 0 | AG53: 155189
A54: OT | B54: UAOT | C54: 51+ km (occupied after 2022) | D54: 50+ | E54: UAOT_O51N | F54: 304427 | G54: 0 | H54: 0 | I54: 6055 | J54: 0 | K54: 304427 | L54: 304427 | M54: 0 | N54: 0 | O54: 6055 | P54: 0 | Q54: 304427 | R54: 304427 | S54: 0 | T54: - | U54: 4 | V54: 0 | W54: 4 | X54: 0 | Y54: 0 | Z54: 3028 | AA54: 0 | AB54: 3028 | AC54: 0 | AE54: 3028 | AF54: 0 | AG54: 3028
A55: OT | B55: UAOT | C55: 51+ km (occupied before 2022) | D55: 50+ | E55: UAOT_O51O | F55: 190590 | G55: 0 | H55: 0 | I55: 3791 | J55: 0 | K55: 190590 | L55: 190590 | M55: 0 | N55: 0 | O55: 3790 | P55: 0 | Q55: 190590 | R55: 190590 | S55: 0 | T55: - | U55: 3 | V55: 0 | W55: 3 | X55: 0 | Y55: 0 | Z55: 948 | AA55: 0 | AB55: 948 | AC55: 0 | AE55: 189 | AF55: 0 | AG55: 189
A56: GCA 0-20 km | B56: UAGC | C56: 0-20 km GCA | D56: 0-20km | E56: UAGC_U20A | F56: 1104543 | G56: 1104543 | H56: 0 | I56: 428256 | J56: 1104543 | K56: 0 | L56: 1104543 | M56: 1004983 | N56: 0 | O56: 428256 | P56: 328817 | Q56: 0 | R56: 1004983 | S56: 0 | T56: - | U56: 5 | V56: - | W56: - | X56: 982830 | Y56: 0 | Z56: 214128 | AA56: 134864 | AB56: 982830 | AC56: 982830 | AE56: 214128 | AF56: 134864 | AG56: 982830
A57: GCA 21-50 km | B57: UAGC | C57: 21-50 km GCA | D57: 20-50km | E57: UAGC_U50A | F57: 2459334 | G57: 1228260.2 | H57: 0 | I57: 297609 | J57: 1228261 | K57: 0 | L57: 1525869.2 | M57: 1080945 | N57: 0 | O57: 297609 | P57: 287226 | Q57: 0 | R57: 1378554 | S57: 0 | T57: - | U57: 4 | V57: - | W57: - | X57: 936915 | Y57: 0 | Z57: 152603 | AA57: 104087 | AB57: 1193605 | AC57: 933328 | AE57: 152602 | AF57: 94697 | AG57: 1180627
A58: GCA 51+ km | B58: UAGC | C58: 51+ km GCA | D58: 50+ | E58: UAGC_U51P | F58: 23881586 | G58: 0 | H58: 0 | I58: 1643127 | J58: 0 | K58: 6407207 | L58: 6407207 | M58: 0 | N58: 0 | O58: 1643127 | P58: 0 | Q58: 5048344.3 | R58: 5048344.3 | S58: 0 | T58: - | U58: 3 | V58: - | W58: - | X58: 0 | Y58: 0 | Z58: 432427 | AA58: 0 | AB58: 432427 | AC58: 0 | AE58: 86485 | AF58: 0 | AG58: 86485
A59: Total | F59: =SUM(F8:F55) -> 28390704 | G59: =SUM(G8:G55) -> 2783027.2 | H59: =SUBTOTAL(109,wand_total[ndp_aff_sp2_joint]) -> 0 | I59: =SUBTOTAL(109,wand_total[ndp_aff_sp3_joint]) -> 2400352 | J59: =SUM(J8:J55) -> 2783028 | K59: =SUBTOTAL(109,wand_total[ndp_aff_sp5_joint]) -> 6902224 | L59: =SUBTOTAL(109,wand_total[ndp_aff_total_joint]) -> 9982860.1 | M59: =SUM(M8:M55) -> 2536152 | N59: =SUBTOTAL(109,wand_total[ndp_pin_sp2_joint]) -> 0 | O59: =SUBTOTAL(109,wand_total[ndp_pin_sp3_joint]) -> 2400351 | P59: =SUM(P8:P55) -> 616043 | Q59: =SUBTOTAL(109,wand_total[ndp_pin_sp5_joint]) -> 5543361.3 | R59: =SUBTOTAL(109,wand_total[ndp_pin_total_joint]) -> 8377122.3 | X59: =SUM(X8:X55) -> 2200151 | Y59: =SUBTOTAL(109,wand_total[ndp_target_sp2_joint]) -> 0 | Z59: =SUBTOTAL(109,wand_total[ndp_target_sp3_joint]) -> 813891 | AA59: =SUM(AA8:AA55) -> 238951 | AB59: =SUBTOTAL(109,wand_total[ndp_target_total_joint]) -> 2896487 | AC59: =SUM(AC8:AC55) -> 2196564 | AD59: =SUBTOTAL(109,wand_total[ndp_targetPr_sp2_joint]) -> 0 | AE59: =SUBTOTAL(109,wand_total[ndp_targetPr_sp3_joint]) -> 467189 | AF59: =SUM(AF8:AF55) -> 229561 | AG59: =SUBTOTAL(109,wand_total[ndp_targetPr_total_joint]) -> 2536808
F61: Cells shaded in yellow are aggregated values that are repetative of other records/zones in the table.

Sheet SP#1 Overall
A1: UKRAINE 2026 HNRP
A2: SP1: Overall | People Affected, PiN, Target and Prioritized Target by Cluster
A3: =ActivityList!A3 -> Release Date: 13 January 2026 | I3: ="sp1_overall_pin_"&I4 -> sp1_overall_pin_ed | J3: ="sp1_overall_pin_"&J4 -> sp1_overall_pin_fs | K3: ="sp1_overall_pin_"&K4 -> sp1_overall_pin_he | L3: ="sp1_overall_pin_"&L4 -> sp1_overall_pin_pr | M3: ="sp1_overall_pin_"&M4 -> sp1_overall_pin_sn | N3: ="sp1_overall_pin_"&N4 -> sp1_overall_pin_wa | O3: ="sp1_overall_pin_"&O4 -> sp1_overall_pin_gp | P3: ="sp1_overall_pin_"&P4 -> sp1_overall_pin_cp | Q3: ="sp1_overall_pin_"&Q4 -> sp1_overall_pin_gb
I4: ed | J4: fs | K4: he | L4: pr | M4: sn | N4: wa | O4: gp | P4: cp | Q4: gb
A5: Oblast | C5: Analysis Zones | F5: # Affected People | I5: # People in Need (Individuals) | O5: Protection AoRs | R5: FSL AoRs | T5: Joint PiN | U5: Cluster Severity Phase | AA5: Protection AoRs | AD5: FSL AoRs | AF5: Intersectoral | AG5: # Target (Individuals) | AM5: Protection AoRs | AP5: FSL AoRs | AS5: Total | AT5: # Prioritized Target (Individuals) | AZ5: Protection AoRs | BC5: FSL AoRs | BF5: Total
A6: Name (English) | B6: Pcode | C6: Geographical Zone | D6: Swath | E6: Code | F6: IDP | G6: Non-Displ. | H6: Overall | I6: ED | J6: FL | K6: HE | L6: PR | M6: SN | N6: WA | O6: GP | P6: CP | Q6: GB | R6: FS | S6: LI | U6: ED | V6: FL | W6: HE | X6: PR | Y6: SN | Z6: WA | AA6: GP | AB6: CP | AC6: GB | AD6: FS | AE6: LI | AF6: Severity | AG6: ED | AH6: FL | AI6: HE | AJ6: PR | AK6: SN | AL6: WA | AM6: GP | AN6: CP | AO6: GB | AP6: FS | AQ6: LI | AR6: CW | AT6: ED | AU6: FL | AV6: HE | AW6: PR | AX6: SN | AY6: WA | AZ6: GP | BA6: CP | BB6: GB | BC6: FS | BD6: LI | BE6: CW
A7: ADM1_EN | B7: ADM1_PCODE | C7: geo_zone | D7: swath | E7: UoA_code | F7: idp_aff_sp1 | G7: ndp_aff_sp1 | H7: overall_aff_sp1 | I7: sp1_overall_pin_ed | J7: sp1_overall_pin_fl | K7: sp1_overall_pin_he | L7: sp1_overall_pin_pr | M7: sp1_overall_pin_sn | N7: sp1_overall_pin_wa | O7: sp1_overall_pin_gp | P7: sp1_overall_pin_cp | Q7: sp1_overall_pin_gb | R7: sp1_overall_pin_fs | S7: sp1_overall_pin_li | T7: sp1_overall_pin_adopted | U7: sp1_overall_sev_ed | V7: sp1_overall_sev_fl | W7: sp1_overall_sev_he | X7: sp1_overall_sev_pr | Y7: sp1_overall_sev_sn | Z7: sp1_overall_sev_wa | AA7: sp1_overall_sev_gp | AB7: sp1_overall_sev_cp | AC7: sp1_overall_sev_gb | AD7: sp1_overall_sev_fs | AE7: sp1_overall_sev_li | AF7: sp1_overall_sev_adopted | AG7: sp1_overall_target_ed | AH7: sp1_overall_target_fl | AI7: sp1_overall_target_he | AJ7: sp1_overall_target_pr | AK7: sp1_overall_target_sn | AL7: sp1_overall_target_wa | AM7: sp1_overall_target_gp | AN7: sp1_overall_target_cp | AO7: sp1_overall_target_gb | AP7: sp1_overall_target_fs | AQ7: sp1_overall_target_li | AR7: sp1_overall_target_cw | AS7: sp1_overall_target_joint | AT7: sp1_overall_targetPr_ed | AU7: sp1_overall_targetPr_fl | AV7: sp1_overall_targetPr_he | AW7: sp1_overall_targetPr_pr | AX7: sp1_overall_targetPr_sn | AY7: sp1_overall_targetPr_wa | AZ7: sp1_overall_targetPr_gp | BA7: sp1_overall_targetPr_cp | BB7: sp1_overall_targetPr_gb | BC7: sp1_overall_targetPr_fs | BD7: sp1_overall_targetPr_li | BE7: sp1_overall_targetPr_cw | BF7: sp1_overall_targetPr_joint
A8: Vinnytska | B8: UA05 | C8: All oblast | D8: 50+ | E8: UA05_UALL | F8: 0 | G8: 0 | I8: =idp_SP1[[#This Row],[sp1_idp_pin_ed]]+ndp_SP1[[#This Row],[sp1_ndp_pin_ed]] -> 0 | J8: =idp_SP1[[#This Row],[sp1_idp_pin_fl]]+ndp_SP1[[#This Row],[sp1_ndp_pin_fl]] -> 0 | K8: =idp_SP1[[#This Row],[sp1_idp_pin_he]]+ndp_SP1[[#This Row],[sp1_ndp_pin_he]] -> 0 | L8: =idp_SP1[[#This Row],[sp1_idp_pin_pr]]+ndp_SP1[[#This Row],[sp1_ndp_pin_pr]] -> 0 | M8: =idp_SP1[[#This Row],[sp1_idp_pin_sn]]+ndp_SP1[[#This Row],[sp1_ndp_pin_sn]] -> 0 | N8: =idp_SP1[[#This Row],[sp1_idp_pin_wa]]+ndp_SP1[[#This Row],[sp1_ndp_pin_wa]] -> 0 | O8: =idp_SP1[[#This Row],[sp1_idp_pin_gp]]+ndp_SP1[[#This Row],[sp1_ndp_pin_gp]] -> 0 | P8: =idp_SP1[[#This Row],[sp1_idp_pin_cp]]+ndp_SP1[[#This Row],[sp1_ndp_pin_cp]] -> 0 | Q8: =idp_SP1[[#This Row],[sp1_idp_pin_gb]]+ndp_SP1[[#This Row],[sp1_ndp_pin_gb]] -> 0 | R8: =idp_SP1[[#This Row],[sp1_idp_pin_fs]]+ndp_SP1[[#This Row],[sp1_ndp_pin_fs]] -> 0 | S8: =idp_SP1[[#This Row],[sp1_idp_pin_li]]+ndp_SP1[[#This Row],[sp1_ndp_pin_li]] -> 0 | T8: =idp_SP1[[#This Row],[sp1_idp_pin_adopted]]+ndp_SP1[[#This Row],[sp1_ndp_pin_adopted]] -> 0 | X8: =MAX(idp_SP1[[#This Row],[sp1_idp_sev_pr]],ndp_SP1[[#This Row],[sp1_ndp_sev_pr]]) -> 0 | Y8: 0 | AG8: =idp_SP1[[#This Row],[sp1_idp_target_ed]]+ndp_SP1[[#This Row],[sp1_ndp_target_ed]] -> 0 | AH8: =idp_SP1[[#This Row],[sp1_idp_target_fl]]+ndp_SP1[[#This Row],[sp1_ndp_target_fl]] -> 0 | AI8: =idp_SP1[[#This Row],[sp1_idp_target_he]]+ndp_SP1[[#This Row],[sp1_ndp_target_he]] -> 0 | AJ8: =idp_SP1[[#This Row],[sp1_idp_target_pr]]+ndp_SP1[[#This Row],[sp1_ndp_target_pr]] -> 0 | AK8: =idp_SP1[[#This Row],[sp1_idp_target_sn]]+ndp_SP1[[#This Row],[sp1_ndp_target_sn]] -> 0 | AL8: =idp_SP1[[#This Row],[sp1_idp_target_wa]]+ndp_SP1[[#This Row],[sp1_ndp_target_wa]] -> 0 | AM8: =idp_SP1[[#This Row],[sp1_idp_target_gp]]+ndp_SP1[[#This Row],[sp1_ndp_target_gp]] -> 0 | AN8: =idp_SP1[[#This Row],[sp1_idp_target_cp]]+ndp_SP1[[#This Row],[sp1_ndp_target_cp]] -> 0 | AO8: =idp_SP1[[#This Row],[sp1_idp_target_gb]]+ndp_SP1[[#This Row],[sp1_ndp_target_gb]] -> 0 | AP8: =idp_SP1[[#This Row],[sp1_idp_target_fs]]+ndp_SP1[[#This Row],[sp1_ndp_target_fs]] -> 0 | AQ8: =idp_SP1[[#This Row],[sp1_idp_target_li]]+ndp_SP1[[#This Row],[sp1_ndp_target_li]] -> 0 | AR8: =idp_SP1[[#This Row],[sp1_idp_target_cw]]+ndp_SP1[[#This Row],[sp1_ndp_target_cw]] -> 0 | AS8: =idp_SP1[[#This Row],[sp1_idp_target_joint]]+ndp_SP1[[#This Row],[sp1_ndp_target_joint]] -> 0 | AT8: 0 | AU8: 0 | AV8: 0 | AW8: 0 | AX8: 0 | AY8: 0 | AZ8: 0 | BA8: 0 | BB8: 0 | BC8: 0 | BD8: 0 | BE8: 0 | BF8: 0
